Workbook

Sheet Summary
A1: FinOps SaaS — Feature Build Status
A2: Source: IMPLEMENTATION_STATUS_MATRIX.md reconciled with lumen.html (commit f4795a4, May 24, 2026). Update Status on Feature Tracker sheet; this page recalculates.
A4: Category | B4: Built | C4: Partial | D4: In Progress | E4: Not Built | F4: Total | G4: % Complete
A5: Dashboards & Visualization | B5: =COUNTIFS('Feature Tracker'!$A$2:$A$69,A5,'Feature Tracker'!$E$2:$E$69,"Built") -> 9 | C5: =COUNTIFS('Feature Tracker'!$A$2:$A$69,A5,'Feature Tracker'!$E$2:$E$69,"Partial") -> 0 | D5: =COUNTIFS('Feature Tracker'!$A$2:$A$69,A5,'Feature Tracker'!$E$2:$E$69,"In Progress") -> 0 | E5: =COUNTIFS('Feature Tracker'!$A$2:$A$69,A5,'Feature Tracker'!$E$2:$E$69,"Not Built") -> 2 | F5: =SUM(B5:E5) -> 11 | G5: =IF(F5=0,0,(B5+0.5*C5)/F5) -> 0.81818182
A6: Cost Aggregation (Backend) | B6: =COUNTIFS('Feature Tracker'!$A$2:$A$69,A6,'Feature Tracker'!$E$2:$E$69,"Built") -> 8 | C6: =COUNTIFS('Feature Tracker'!$A$2:$A$69,A6,'Feature Tracker'!$E$2:$E$69,"Partial") -> 0 | D6: =COUNTIFS('Feature Tracker'!$A$2:$A$69,A6,'Feature Tracker'!$E$2:$E$69,"In Progress") -> 0 | E6: =COUNTIFS('Feature Tracker'!$A$2:$A$69,A6,'Feature Tracker'!$E$2:$E$69,"Not Built") -> 0 | F6: =SUM(B6:E6) -> 8 | G6: =IF(F6=0,0,(B6+0.5*C6)/F6) -> 1
A7: Cost Normalization | B7: =COUNTIFS('Feature Tracker'!$A$2:$A$69,A7,'Feature Tracker'!$E$2:$E$69,"Built") -> 3 | C7: =COUNTIFS('Feature Tracker'!$A$2:$A$69,A7,'Feature Tracker'!$E$2:$E$69,"Partial") -> 0 | D7: =COUNTIFS('Feature Tracker'!$A$2:$A$69,A7,'Feature Tracker'!$E$2:$E$69,"In Progress") -> 0 | E7: =COUNTIFS('Feature Tracker'!$A$2:$A$69,A7,'Feature Tracker'!$E$2:$E$69,"Not Built") -> 0 | F7: =SUM(B7:E7) -> 3 | G7: =IF(F7=0,0,(B7+0.5*C7)/F7) -> 1
A8: Credential Management | B8: =COUNTIFS('Feature Tracker'!$A$2:$A$69,A8,'Feature Tracker'!$E$2:$E$69,"Built") -> 8 | C8: =COUNTIFS('Feature Tracker'!$A$2:$A$69,A8,'Feature Tracker'!$E$2:$E$69,"Partial") -> 0 | D8: =COUNTIFS('Feature Tracker'!$A$2:$A$69,A8,'Feature Tracker'!$E$2:$E$69,"In Progress") -> 0 | E8: =COUNTIFS('Feature Tracker'!$A$2:$A$69,A8,'Feature Tracker'!$E$2:$E$69,"Not Built") -> 1 | F8: =SUM(B8:E8) -> 9 | G8: =IF(F8=0,0,(B8+0.5*C8)/F8) -> 0.88888889
A9: Budgeting & Cost Control | B9: =COUNTIFS('Feature Tracker'!$A$2:$A$69,A9,'Feature Tracker'!$E$2:$E$69,"Built") -> 3 | C9: =COUNTIFS('Feature Tracker'!$A$2:$A$69,A9,'Feature Tracker'!$E$2:$E$69,"Partial") -> 2 | D9: =COUNTIFS('Feature Tracker'!$A$2:$A$69,A9,'Feature Tracker'!$E$2:$E$69,"In Progress") -> 0 | E9: =COUNTIFS('Feature Tracker'!$A$2:$A$69,A9,'Feature Tracker'!$E$2:$E$69,"Not Built") -> 1 | F9: =SUM(B9:E9) -> 6 | G9: =IF(F9=0,0,(B9+0.5*C9)/F9) -> 0.66666667
A10: Optimization & Recommendations | B10: =COUNTIFS('Feature Tracker'!$A$2:$A$69,A10,'Feature Tracker'!$E$2:$E$69,"Built") -> 2 | C10: =COUNTIFS('Feature Tracker'!$A$2:$A$69,A10,'Feature Tracker'!$E$2:$E$69,"Partial") -> 3 | D10: =COUNTIFS('Feature Tracker'!$A$2:$A$69,A10,'Feature Tracker'!$E$2:$E$69,"In Progress") -> 0 | E10: =COUNTIFS('Feature Tracker'!$A$2:$A$69,A10,'Feature Tracker'!$E$2:$E$69,"Not Built") -> 1 | F10: =SUM(B10:E10) -> 6 | G10: =IF(F10=0,0,(B10+0.5*C10)/F10) -> 0.58333333
A11: Security & Access Control | B11: =COUNTIFS('Feature Tracker'!$A$2:$A$69,A11,'Feature Tracker'!$E$2:$E$69,"Built") -> 5 | C11: =COUNTIFS('Feature Tracker'!$A$2:$A$69,A11,'Feature Tracker'!$E$2:$E$69,"Partial") -> 0 | D11: =COUNTIFS('Feature Tracker'!$A$2:$A$69,A11,'Feature Tracker'!$E$2:$E$69,"In Progress") -> 0 | E11: =COUNTIFS('Feature Tracker'!$A$2:$A$69,A11,'Feature Tracker'!$E$2:$E$69,"Not Built") -> 3 | F11: =SUM(B11:E11) -> 8 | G11: =IF(F11=0,0,(B11+0.5*C11)/F11) -> 0.625
A12: User Management | B12: =COUNTIFS('Feature Tracker'!$A$2:$A$69,A12,'Feature Tracker'!$E$2:$E$69,"Built") -> 2 | C12: =COUNTIFS('Feature Tracker'!$A$2:$A$69,A12,'Feature Tracker'!$E$2:$E$69,"Partial") -> 1 | D12: =COUNTIFS('Feature Tracker'!$A$2:$A$69,A12,'Feature Tracker'!$E$2:$E$69,"In Progress") -> 0 | E12: =COUNTIFS('Feature Tracker'!$A$2:$A$69,A12,'Feature Tracker'!$E$2:$E$69,"Not Built") -> 2 | F12: =SUM(B12:E12) -> 5 | G12: =IF(F12=0,0,(B12+0.5*C12)/F12) -> 0.5
A13: APIs & Integrations | B13: =COUNTIFS('Feature Tracker'!$A$2:$A$69,A13,'Feature Tracker'!$E$2:$E$69,"Built") -> 1 | C13: =COUNTIFS('Feature Tracker'!$A$2:$A$69,A13,'Feature Tracker'!$E$2:$E$69,"Partial") -> 0 | D13: =COUNTIFS('Feature Tracker'!$A$2:$A$69,A13,'Feature Tracker'!$E$2:$E$69,"In Progress") -> 0 | E13: =COUNTIFS('Feature Tracker'!$A$2:$A$69,A13,'Feature Tracker'!$E$2:$E$69,"Not Built") -> 6 | F13: =SUM(B13:E13) -> 7 | G13: =IF(F13=0,0,(B13+0.5*C13)/F13) -> 0.14285714
A14: Advanced Analytics | B14: =COUNTIFS('Feature Tracker'!$A$2:$A$69,A14,'Feature Tracker'!$E$2:$E$69,"Built") -> 0 | C14: =COUNTIFS('Feature Tracker'!$A$2:$A$69,A14,'Feature Tracker'!$E$2:$E$69,"Partial") -> 1 | D14: =COUNTIFS('Feature Tracker'!$A$2:$A$69,A14,'Feature Tracker'!$E$2:$E$69,"In Progress") -> 0 | E14: =COUNTIFS('Feature Tracker'!$A$2:$A$69,A14,'Feature Tracker'!$E$2:$E$69,"Not Built") -> 2 | F14: =SUM(B14:E14) -> 3 | G14: =IF(F14=0,0,(B14+0.5*C14)/F14) -> 0.16666667
A15: Settings | B15: =COUNTIFS('Feature Tracker'!$A$2:$A$69,A15,'Feature Tracker'!$E$2:$E$69,"Built") -> 0 | C15: =COUNTIFS('Feature Tracker'!$A$2:$A$69,A15,'Feature Tracker'!$E$2:$E$69,"Partial") -> 0 | D15: =COUNTIFS('Feature Tracker'!$A$2:$A$69,A15,'Feature Tracker'!$E$2:$E$69,"In Progress") -> 0 | E15: =COUNTIFS('Feature Tracker'!$A$2:$A$69,A15,'Feature Tracker'!$E$2:$E$69,"Not Built") -> 2 | F15: =SUM(B15:E15) -> 2 | G15: =IF(F15=0,0,(B15+0.5*C15)/F15) -> 0
A16: TOTAL | B16: =SUM(B5:B15) -> 41 | C16: =SUM(C5:C15) -> 7 | D16: =SUM(D5:D15) -> 0 | E16: =SUM(E5:E15) -> 20 | F16: =SUM(F5:F15) -> 68 | G16: =IF(F16=0,0,(B16+0.5*C16)/F16) -> 0.65441176
A18: Recommended next steps (per roadmap):
A19: Phase 10: Azure + GCP credential UIs (26 pts, ~2 wks)
A20: Phase 12: RBAC framework, backend user mgmt, audit logging (68 pts, ~3 wks)
A21: Phase 13: Budget management + alerts (34 pts, ~2.5 wks)
A22: Phase 14: Recommendation integration + cost impact tracking (34 pts)

Sheet Feature Tracker
A1: Category | B1: Feature | C1: Sub-Feature / Detail | D1: Cloud Scope | E1: Status | F1: Phase | G1: Story Points | H1: Notes
A2: Dashboards & Visualization | B2: Executive Summary | C2: C-level view, forecasts, strategic insights | D2: Multi-cloud | E2: Built | F2: Done | H2: In lumen.html
A3: Dashboards & Visualization | B3: Finance Portal | C3: 90-day trends, cost drivers, account breakdown | D3: Multi-cloud | E3: Built | F3: Done | H3: In lumen.html
A4: Dashboards & Visualization | B4: FinOps Analytics | C4: Service breakdown, AI services, recommendations | D4: Multi-cloud | E4: Built | F4: Done | H4: In lumen.html
A5: Dashboards & Visualization | B5: Team Cost Dashboard | C5: Cost allocation, budgets, team resources | D5: Multi-cloud | E5: Built | F5: Done | H5: In lumen.html
A6: Dashboards & Visualization | B6: AWS Dashboard | C6: AWS metrics, RI/SP, account hierarchy | D6: AWS | E6: Built | F6: 11 | G6: 13 | H6: Added May 24, 2026 (commit f4795a4)
A7: Dashboards & Visualization | B7: Azure Dashboard | C7: Azure metrics, reservations, subscriptions | D7: Azure | E7: Built | F7: 11 | G7: 13 | H7: Added May 24, 2026
A8: Dashboards & Visualization | B8: GCP Dashboard | C8: GCP metrics, CUD, projects | D8: GCP | E8: Built | F8: 11 | G8: 13 | H8: Added May 24, 2026
A9: Dashboards & Visualization | B9: FOCUS Normalized View | C9: Unified cross-cloud view using FOCUS fields | D9: Multi-cloud | E9: Built | F9: 11 | G9: 21 | H9: Added May 24, 2026
A10: Dashboards & Visualization | B10: AI Cost Dashboard | C10: Model costs, token analytics, optimization | D10: Multi-cloud | E10: Built | F10: 11 | G10: 21 | H10: In lumen.html
A11: Dashboards & Visualization | B11: Custom Dashboard Builder | C11: Drag-and-drop dashboard creation | D11: Multi-cloud | E11: Not Built | F11: 16
A12: Dashboards & Visualization | B12: Scheduled Reports | C12: Report generation and distribution | D12: Multi-cloud | E12: Not Built | F12: 16
A13: Cost Aggregation (Backend) | B13: Cost Ingestion Engine | C13: AWS CUR via S3 | D13: AWS | E13: Built | F13: Done | H13: Complete backend
A14: Cost Aggregation (Backend) | B14: Cost Ingestion Engine | C14: Azure Cost Management API | D14: Azure | E14: Built | F14: Done
A15: Cost Aggregation (Backend) | B15: Cost Ingestion Engine | C15: GCP BigQuery billing export | D15: GCP | E15: Built | F15: Done
A16: Cost Aggregation (Backend) | B16: Cost Schema Mapping | C16: Provider schema -> internal schema | D16: All | E16: Built | F16: Done
A17: Cost Aggregation (Backend) | B17: Service Categorization | C17: 25+ AWS, 25+ Azure, 30+ GCP services | D17: All | E17: Built | F17: Done
A18: Cost Aggregation (Backend) | B18: Multi-Tenant Isolation | C18: Tenant separation in ingestion | D18: All | E18: Built | F18: Done
A19: Cost Aggregation (Backend) | B19: Job Scheduling | C19: cost_ingest, focus_transform jobs | D19: All | E19: Built | F19: Done
A20: Cost Aggregation (Backend) | B20: Data Pipeline Monitoring | C20: Job status tracking | D20: All | E20: Built | F20: Done
A21: Cost Normalization | B21: FOCUS Schema Transformation | C21: invoice_issuer, service_name, service_category | D21: All | E21: Built | F21: Done
A22: Cost Normalization | B22: AI Service Classification | C22: Claude, GPT-4, Vertex AI, etc. | D22: All | E22: Built | F22: Done
A23: Cost Normalization | B23: Multi-Cloud Comparison | C23: Cross-cloud analysis via FOCUS dashboard | D23: All | E23: Built | F23: 11 | H23: Unblocked by FOCUS dashboard (May 24)
A24: Credential Management | B24: AWS Credential UI | C24: Create/edit/delete S3 config, test connection | D24: AWS | E24: Built | F24: Done
A25: Credential Management | B25: Azure Credential UI | C25: Service Principal auth, Cost API connection | D25: Azure | E25: Built | F25: 10 | G25: 13 | H25: Built Jul 9, 2026 — unified CredentialManager.jsx with setup guides; wired to /api/v1 endpoints
A26: Credential Management | B26: GCP Credential UI | C26: Service Account auth, BigQuery connection | D26: GCP | E26: Built | F26: 10 | G26: 13 | H26: Built Jul 9, 2026 — unified CredentialManager.jsx with setup guides; wired to /api/v1 endpoints
A27: Credential Management | B27: Multi-Cloud Admin Hub | C27: Unified credential view, provider status, sync metrics | D27: All | E27: Built | F27: 10 | G27: 21 | H27: Added May 24, 2026
A28: Credential Management | B28: Config Validation (backend) | C28: All three clouds | D28: All | E28: Built | F28: Done
A29: Credential Management | B29: Test Connection (backend) | C29: All three clouds | D29: All | E29: Built | F29: Done
A30: Credential Management | B30: Credential Encryption | C30: DB-level encryption | D30: All | E30: Built | F30: Done
A31: Credential Management | B31: Credential Rotation | C31: Automated key rotation | D31: All | E31: Not Built | F31: 13
A32: Credential Management | B32: Multi-Config Support | C32: Multiple configs per provider | D32: All | E32: Built | F32: Done
A33: Budgeting & Cost Control | B33: Budget Tracking | C33: Basic tracking in Team Dashboard | D33: Multi-cloud | E33: Built | F33: 13 | H33: Built Jul 11, 2026 — live actuals from FocusCost, utilization %, Live view in Budgets screen
A34: Budgeting & Cost Control | B34: Budget Creation | C34: Hierarchical budget builder | D34: Multi-cloud | E34: Built | F34: 13 | G34: 21 | H34: Built Jul 11, 2026 — /api/budgets CRUD, scoped by provider/category/account, RBAC-guarded
A35: Budgeting & Cost Control | B35: Budget vs Actual | C35: Variance tracking | D35: Multi-cloud | E35: Built | F35: 13 | H35: Built Jul 11, 2026 — per-period + monthly history endpoint
A36: Budgeting & Cost Control | B36: Forecasting | C36: Spend forecasting | D36: Multi-cloud | E36: Partial | F36: 16 | H36: Run-rate EOP forecast per budget built Jul 11; ML models pending
A37: Budgeting & Cost Control | B37: Alerts & Notifications | C37: Threshold alerts | D37: Multi-cloud | E37: Partial | F37: 13 | G37: 13 | H37: Threshold alerts (warning/over) in API+UI built Jul 11; email/Slack delivery pending
A38: Budgeting & Cost Control | B38: Budget Enforcement | C38: Hard limits / actions | D38: Multi-cloud | E38: Not Built | F38: 13
A39: Optimization & Recommendations | B39: Cost Optimization Recommendations | C39: Static examples in FinOps Analytics | D39: Multi-cloud | E39: Built | F39: 14 | H39: Built Jul 11, 2026 — cost_recommendations.py: 3 detectors over FOCUS data, verified $4.6k/mo findings
A40: Optimization & Recommendations | B40: CSP-Native Recommendations | C40: Trusted Advisor, Azure Advisor, GCP Recommender | D40: All | E40: Partial | F40: 14 | G40: 21 | H40: Rule-based equivalents (SP/RI/CUD coverage, rightsizing, unused commitments) built Jul 11; direct Advisor API pulls pending
...
